<?xml version="1.0"?>
<robot xmlns:xacro="http://wiki.ros.org/xacro">
  <xacro:macro name="agv" params="
    agv_number
    y_position">
    
    <xacro:include filename="$(find ariac_description)/urdf/AGV/agv.ros2_control.xacro"/>

    <!-- Run ROS2 control macro -->
    <xacro:agv_ros2_control name="${agv_number}"/>

    <link name="${agv_number}_track">
      <inertial>
        <mass value="100"/>
        <inertia ixx="1.0" ixy="0.0" ixz="0.0" iyy="1.0" iyz="0.0" izz="1.0"/>
      </inertial>
    </link>

    <link name="${agv_number}_base">      
      <visual>
        <geometry>
          <mesh filename="file://$(find ariac_description)/meshes/AGV/robot.dae" scale="1 -1 1"/>
        </geometry>
      </visual>
      <collision>
        <geometry>
          <mesh filename="file://$(find ariac_description)/meshes/AGV/robot.dae" scale="1 -1 1"/>
        </geometry>
      </collision>
      <inertial>
        <origin xyz="0 0 0" rpy="0 0 0"/>
        <mass value="50.0"/>
        <inertia
            ixx="4.525499333333333" ixy="0.0" ixz="0.0"
            iyy="1.4504741933333334" iyz="0.0"
            izz="5.6426401933333326"/>
      </inertial>
    </link>

    <link name="${agv_number}_tray">
      <visual>
        <geometry>
          <mesh filename="file://$(find ariac_description)/meshes/AGV/kit_tray.stl" scale="1 1 1"/>
        </geometry>
      </visual>
      
      <collision>
        <geometry>
          <mesh filename="file://$(find ariac_description)/meshes/AGV/kit_tray.stl" scale="1 1 1"/>
        </geometry>
      </collision>
      
      <inertial>
        <origin xyz="0 0 0" rpy="0 0 0"/>
        <mass value="1"/>
        <inertia ixx="0.0408" ixy="0.0" ixz="0.0" iyy="0.02084" iyz="0.0" izz="0.0616"/>
      </inertial>
    </link>

    <gazebo reference="${agv_number}_tray">
      <material>Gazebo/Gray</material>
    </gazebo>

    <joint name="world_to_track" type="fixed">
      <parent link="world"/>
      <child link="${agv_number}_track"/>
      <origin xyz="-2.27 ${y_position} 0.0" rpy="0.0 0.0 ${pi/2}"/>
    </joint>

    <joint name="agv_joint" type="prismatic">
      <axis xyz="0 1 0"/>
      <origin xyz="0.0 0.0 0.0"/>
      <parent link="${agv_number}_track"/>
      <child link="${agv_number}_base"/>
      <limit effort="1000.0" lower="0" upper="11" velocity="10"/>
      <dynamics damping="20.0" friction="500.0" />
    </joint>

    <joint name="kit_tray" type="fixed">
      <parent link="${agv_number}_base"/>
      <child link="${agv_number}_tray"/>
      <origin xyz="0 -0.2 0.75" rpy="0.0 0.0 0.0"/>
    </joint>

  </xacro:macro>
</robot>